Workbook

Sheet chapters
A1: Chapter | B1: First_Author | C1: Title | D1: Received | E1: Accepted | F1: Published_online | G1: DOI | H1: Authors | I1: Abstract | J1: Keywords
A2: 0 | B2: Deruytter & Veldkamp | C2: Editorial: Why guidelines and standardization in insect research? | D2: 45627 | E2: 45637 | F2: 45838 | G2: https://doi.org/10.1163/23524588-bja10151 | H2: D. Deruytter, T. Veldkamp | I2: Research on the use of insects as a source of food and feed is experiencing significant growth, as it may contribute to the transition from linear agricultural practices to a more sustainable circular system (van Huis and Oonincx, 2017). For instance, a search in Google Scholar for articles containing “Tenebrio molitor” or “Hermetia illucens” in the title reveals an increase in publications from 115 in 2014 to 961 in 2023 (Figure 1), compared to a total of only 534 publications from 2004 to 2013. This growth rate surpasses the overall increase in scientific publications over a similar period (47% from 2016 to 2022; Hanson et al., 2024), indicating a rising interest and engagement in this emerging field.
A3: 1 | B3: Coudron et al. | C3: Basic information and good practices on how to maintain stock populations for <i>Tenebrio molitor</i> and <i>Hermetia illucens</i> for research | D3: 45632 | E3: 45789 | F3: 45805 | G3: https://doi.org/10.1163/23524588-bja10240 | H3: C.L. Coudron, C. Adamaki-Sotiraki, W. Yakti, J.J. Pascual, V. Wiklicky, C. Sandrock, M. Van Peer, C. Athanassiou, D.A. Peguero, C. Rumbos, S. Naser El Deen, T. Veldkamp, D. Deruytter, M. Cambra-López | I3: The information on the production and reproduction of Tenebrio molitor and Hermetia illucens is essential for researchers pursuing a career in insect farming for food, feed and non-food applications. Rather than requiring researchers to sift through numerous studies to develop effective rearing protocols to maintain a stock population for experimental purposes, the authors summarized insights from peer-reviewed research, while expanding it with their collective experience in rearing these species in both laboratory and pilot-scale settings. A similar approach was applied to both species, beginning with a detailed overview of their life cycle, which is used as a framework for various maintenance procedures. Followed by a description of the environmental conditions in which each species should be held and the minimal infrastructure needed to rear them. Feed recommendations are provided, along with good practices for each stage of the lifecycle, including egg production, instar rearing, and adult handling. The final section addresses potential risks and hazards associated with insect rearing. This includes concerns about the allergenicity of particles produced during rearing, as well as the possibility of contamination, disease outbreaks, or pest infestations. The risks associated with maintaining different insect strains, including cross-contamination and the potential for genetic drift or inbreeding depression, are also discussed. | J3: black soldier fly, breeding, BSF rearing, mealworm
A4: 2 | B4: Deruytter et al. | C4: Considerations for designing and performing insect larvae production experiments | D4: 45627 | E4: 45813 | F4: 45832 | G4: https://doi.org/10.1163/23524588-bja10252 | H4: D. Deruytter, C. Coudron, V. Wiklicky, S. Naser El Deen, M. Van Peer, C. Rumbos, D.A. Peguero, C. Adamaki-Sotiraki, C. Athanassiou, T. Veldkamp, C. Sandrock, W. Yakti | I4: This chapter of the BugBook provides guidance and addresses challenges towards conducting experiments that aim to optimize the production of insects for food and feed, focusing exclusively on Tenebrio molitor (yellow mealworm) and Hermetia illucens (black soldier fly). The goal is to improve the reliability, reproducibility, and efficiency of insect production experiments. This reduces the human and financial resources needed, improves quality, and ensure the broader implementation of the results. Importantly, these guidelines are based on both data from literature and from unpublished experiences of the authors. Most aspects of the experimental systems are discussed, starting with methods to ensure that the laboratory conditions correct, followed by the experimental design and setup, including a focus on the control group, scale, and number of replicates. Thereafter, information is provided on the different aspects that need to be monitored during the experiment and how to conclude or harvest an experiment. The latter includes a discussion on the various criteria for determining the optimal harvest time. Finally, common challenges in working on insect larvae are identified and guidelines towards relevant publication information are provided. | J4: Hermetia illucens, insect production experiments, reproducibility, standardisation, Tenebrio molitor
A5: 3 | B5: Cardoso et al. | C5: Ecotoxicology, hazard and safety in insects | D5: 45639 | E5: 45945 | F5: 45968 | G5: https://doi.org/10.1163/23524588-bja10322 | H5: D.N. Cardoso, M. Prodana, A.R.R. Silva, R.G. Morgado, J.N. Pinto, S. Loureiro | I5: This BugBook article provides an overview of edible insect toxicological concerns, focusing on exposure routes, mechanisms of toxicity, and assessment endpoints relevant to human and environmental health. Insects are exposed to contaminants through dermal, oral, injection, and inhalation routes. This article explores key toxicity mechanisms, including neurotoxicity, endocrine disruption, oxidative stress, and immune suppression, emphasising their implications for toxicity in insects. Methodological approaches to assess the toxicity of contaminants, such as topical application, dietary exposures, bioaccumulation assays, and advanced modelling techniques, are discussed, highlighting their adaptability for edible insect species. Standardised protocols, such as those from the Organisation for Economic Co-operation and Development (OECD) and the International Organisation for Standardisation (ISO), are presented whenever possible (excluding bees). Data analyses, interpretation, and modelling are briefly summarised, along with examples and case studies that highlight the relevance of toxicity testing for ensuring food safety, regulatory compliance, and sustainable insect farming practices. Bioaccumulation studies using toxicokinetics modelling reveal insights into contaminant uptake and elimination in relevant edible insect species, supporting practical applications like depuration periods in rearing facilities. By addressing current gaps in methodologies and providing a roadmap for ecotoxicological research, this article aims to guide policymakers, researchers, and industry stakeholders in promoting safe and sustainable practices for the insect-based food and feed sector. The findings underscore the importance of interdisciplinary collaboration in harmonising global standards, safeguarding public health, and advancing circular bioeconomy goals. | J5: bioaccumulation, edible insects, food safety, risk assessment, toxicity mechanisms
A6: 4 | B6: Tomberlin et al. | C6: Assessing behaviour of insects mass produced as food and feed, using black soldier fly as a model | D6: 45621 | E6: 45771 | F6: 45791 | G6: https://doi.org/10.1163/23524588-bja10225 | H6: J.K. Tomberlin, T. Klammsteiner, N. Lemke, P. Yadav, C. Sandrock | I6: Behavioural research and its applications has a rich history in science with direct applications continuing to expand global understanding of ecosystem function, structure, and evolution. The same can be said for such research as related to the applied sciences including entomology. The purpose of this chapter is to provide context to various approaches for assessing behaviour of insects that are mass produced for food and feed. By using the black soldier fly as a model, various approaches for conducting such research are explored along with providing some perspective on the value of such data for optimising insect production. However, it should be noted that this chapter is not exhaustive with regards to variables that can be examined, or the methods employed. | J6: choice test, electrophysiology, ethology, experimental design, reproduction
A7: 5 | B7: Dearlove et al. | C7: Determining multiple stressor interactions in mass-reared insects based on principles of ecotoxicology | D7: 45632 | E7: 45737 | F7: 45783 | G7: https://doi.org/10.1163/23524588-bja10203 | H7: E. Dearlove, C.A.M. Van Gestel, S. Loureiro, C. Svendsen, M. Lloyd, L. Mugo-Kamiri, J.M. Petersen, E. Bessette, S. Edwards, F.S. Lim, P. Herren, L. Hernández Pelegrı́n, R.D. Pienaar, H. Huditz, A. Mostafaie, J. Pinto, A. Roman, C. Savio, A.R. Slowik, J. Takacs, J.K. Upfold, H. Hesketh | I7: Insect mass-rearing is a rapidly expanding industry for the production of protein for food and feed. These highly productive artificial rearing environments can expose insects to a range of biotic and abiotic stressors, including insect pathogens, which may result in population crashes. Interactions between insect pathogens with multiple stressors can exacerbate the effects of individual pathogens on host insects. However, reliable predictions on the combined effects of individual stressors based on mechanisms of action are lacking within the field of insect pathology. We review how ecotoxicological modelling of multiple stressors can be applied to mass-reared insect systems and discuss the importance of standardization across research fields investigating multiple stressors. Important considerations in multiple stressor terminology, experimental design, endpoints and analysis of results are discussed to improve understanding of multiple stressors and their impact on insects for food and feed. This is essential for ensuring optimal rearing conditions for mass-reared insect populations. | J7: additivity, antagonism, entomopathogens, mixtures, synergism
A8: 6 | B8: Lopes et al. | C8: Critical considerations for evaluating and applying insect frass in agricultural and waste systems | D8: 45622 | E8: 45813 | F8: 45833 | G8: https://doi.org/10.1163/23524588-bja10254 | H8: I.G. Lopes, M. Gómez-Brandón, N. Praeg, J. Claeys, W. Yakti, M. Bitterlich, J.J. Jones, C.-M. Geilfus, T. Klammsteiner | I8: Insect frass is one of the most abundant products in the insect industry, regardless of the farmed species. Rich inorganic matter and plant nutrients, frass isapromising organicamendment that can be used inagriculture. While many benefits and challenges have been reported, several knowledge gapsremain unanswered, regarding the specific characteristics and mechanismsof its effects on soils and plants,particularlyintermsof the processes driving these effects and interactions.This article aimstodiscuss recent research on frass and identify existing knowledge gaps, and propose strategies to improve research methodologies,increase comparability across studies, and generate more robust results.The topics covered include the evaluation offrass effects on soil physical properties,microbiological dynamics and fertility, as well as its effects on plant growth, development, and metabolism. The article also explores the potential offrass as an antimicrobial agent and highlights the need for stabilising and improvingits quality and safety before it is used inagricultural activities.Looking forward,insect frass holds great promise as a sustainable input for agriculture, food production, and feed systems. | J8: fertiliser, soil amendment, protocol, experimental design, hygienisation
A9: 7 | B9: Auger et al. | C9: How to explore and exploit the insect-associated microbiome | D9: 45632 | E9: 45818 | F9: 45842 | G9: https://doi.org/10.1163/23524588-bja10256 | H9: L. Auger, D. Tegtmeier, S. Caccia, T. Klammsteiner, J. De Smet | I9: Large scale insect farming is exploring routes to enhance the efficiency, stability, and safety of the bioconversion of low-value substrates into insect-derived building blocks for food, feed, and fertiliser. Along with optimising insect rearing conditions and genetics, the insect microbiome is fundamental for the physiology, development, and adaptation of its host to various environmental conditions. To efficiently explore and exploit this ecosystem, a thorough understanding of its composition, function, and dynamics is required. This article aspires to provide a synopsis of the methodologies used to probe the insect-associated microbiome, primarily focusing on industrially relevant insect species. Key considerations for sample timing, selection, storage, and processing are discussed, emphasising the importance of standardised approaches to facilitate cross-study comparisons and enhance reproducibility. Marker gene and shotgun metagenomic sequencing are contrasted as means to investigate microbiome features, touching upon their respective (dis)advantages and potential use cases. Cultivation-based methods are essential for functional characterisation and translating the potential of insect-derived microorganisms for industrial applications. Direct isolation and enrichment cultures, along with anaerobic and aerobic cultivation techniques, are discussed as well. Methods to engineer microbiomes, such as axenic rearing and synthetic community assembly, have developed as powerful tools for exploring the role of specific microbes in host physiology. Beyond these approaches, metabolomics and metaproteomics are emerging as insightful techniques to dig deeper into microbiome functionality and host-microbe interactions. This article provides a multifaceted outline for researchers investigating the insect-associated microbiome and emphasises the importance of standardised methodologies and reporting for advancing the field. | J9: Hermetia illucens, Tenebrio molitor, microbiome, sequencing, methodology
A10: 8 | B10: Bruno et al. | C10: Life cycle, reproduction, and morphofunctional characterisation of the gut, fat body, and haemocytes in the black soldier fly | D10: 45626 | E10: 45679 | F10: 45798 | G10: https://doi.org/10.1163/23524588-20250002 | H10: D. Bruno, F. Manas, M. Bonelli, M. Gold, M. Marzari, D. Roma, M.C. Valoroso, A. Montali, J.B. Guillaume, M. Rebora, C. Bressac, N. Herman, S. Caccia, M. Casartelli, G. Tettamanti | I10: Insects are attracting significant attention due to their effectiveness as bioconversion agents for various organic waste and by-products, as well as for their use as raw material in the food and feed sector. Consequently, their potential in creating novel, circular, and sustainable supply chains has been extensively documented, leading to a rapid increase in research on the biology of these animals. In this scenario, the black soldier fly (BSF) has gained considerable popularity. Despite the extraordinary bioconversion capabilities of BSF larvae, several challenges must be addressed to develop and optimise the bioconversion process of a wide range of organic substrates. This effort is accompanied by the need to standardise research protocols. To this end, in this article we present information on the morphological features of developmental stages of BSF, the isolation of larval organs, and methods for studying digestion, immune response, and the reproductive system. | J10: Hermetia illucens, insect morphology, insect physiology, gut in vitro models, insect immunity
A11: 9 | B11: Oonincx et al. | C11: Nutritional requirements for edible insect rearing | D11: 45630 | E11: 45771 | F11: 45799 | G11: https://doi.org/10.1163/23524588-bja10226 | H11: D.G.A.B. Oonincx, M. Gold, G. Bosch, J.B. Guillaume, C.I. Rumbos, S. Naser El Deen, C. Sandrock, S. Bellezza Oddon, C.G. Athanassiou, M. Cambra-López, J.J. Pascual, A.P. Parodi, T. Spranghers, W. Yakti | I11: The rapid expansion of insect farming as a sustainable approach for protein production has led to an accumulation of published research on the use of low-value substrates as insect feed. However, compared to conventional livestock, there is a lack of fundamental knowledge about the nutritional physiology and requirements of insects. Such knowledge can lead to the development of optimised feeding substrates that boost insect performance and nutrient composition. In this chapter, the current knowledge on the nutritional requirements of the most relevant insects produced for food and feed is reviewed, and the methods and assays used to investigate the specific requirements are presented. This description of current knowledge on nutritional requirements of edible insects can be used to design suitable rearing diets and as a foundation to further our understanding of insect nutrition. | J11: coleoptera, diptera, edible insects, nutrient requirements, orthoptera
A12: 10 | B12: Bellezza Oddon et al. | C12: Advancing insect utilization for food and feed: standardizing processing methods, enhancing techno-functional properties, and refining feeding trial protocols | D12: 45642 | E12: 45769 | F12: 45791 | G12: https://doi.org/10.1163/23524588-bja10224 | H12: S. Bellezza Oddon, G. Rossi, V. Bongiorno, L. Gasco, S. Ojha, L. Rastello, M. Renna, L. Rossi Ribeiro, C. Sandrock, O.K. Schlüter, I. Biasato | I12: This study presents specific baseline protocols and actionable recommendations for processing and evaluating insect-derived products for food and feed applications, addressing current gaps in standardization and market integration. Processing methods and the utilization of insect-derived products are two critical aspects intrinsically linked to their market applicability for both food and feed purposes. Therefore, it is imperative to direct research efforts towards these domains, aiming to standardise procedures and products to support broader market adoption. Currently, thermal processing, mechanical fractionation, and enzymatic hydrolysis are among the most common technologies, but differences in temperature, process duration, and input material result in variable products, which might be more suitable for specific applications rather than other. These inconsistencies hamper process standardization as well as stakeholder and market confidence. To address this, the study proposes a set of core variables – including moisture content, processing temperature, and duration – that should be consistently reported in scientific publications to enhance reproducibility and facilitate quality benchmarking. Conversely, the evaluation of insect-derived products as feed ingredients parallels the inclusion of other raw materials into animal diets. Similarities include assessing their nutritional value, digestibility, and compatibility with existing feed formulations. However, the integration of insect-based feed ingredients also necessitates addressing several unique recommendations and considerations that are specific to insects and their derivatives. Notably, the study identifies the need for refined protein quantification techniques (e.g. adjusted N conversion factors) that account for chitin and other non-protein nitrogen sources. Furthermore, insect-derived products are inherently diverse, encompassing a wide range of forms, including dried powders, liquid extracts, whole (live) insects, and processed meals. Each of these product types presents distinct challenges and opportunities in terms of their handling, storage, and integration into feed systems. To guide future application, we outline tailored strategies for each product type, emphasizing the importance of interdisciplinary research spanning animal physiology, behavior, and nutrition. Overall, this work provides a structured framework to advance the standardization, comparability, and integration of insect-derived products across the food and feed sectors. | J12: alternative protein, edible insect, insect meal, livestock, reproducibility
A13: 11 | B13: Sandrock et al. | C13: Genetics of insects as food and feed | D13: 45628 | E13: 45824 | F13: 45847 | G13: https://doi.org/10.1163/23524588-bja10260 | H13: C. Sandrock, T.N. Generalovic, K. Paul, G.E.L. Petersen, E. Sellem, M.B. Smith, M. Tapio, W. Yakti, L.W. Beukeboom, D. Deruytter, C.D. Jiggins, T. Lefebvre, P. Librado, B.A. Pannebakker, C.J. Picard, C. Rhode, J.G. Sørensen, A.C. Bouwman, L.S. Hansen, J. Obšteter | I13: Just like traditional livestock, farmed insects harbour genetic variation and can be selectively bred to optimise traits of interest. This BugBook article presents a comprehensive overview of how genetics can contribute to improving insect production for food and feed. Molecular genetics and genomics approaches for generating the data essential for understanding species biology are presented, as well as their implementation in dedicated selective breeding programmes, and options for health and quality control of mass rearing operations. To harness the breeding potential of farmed insects, methods to investigate population genetic diversity and structure through population and evolutionary genetic principles are provided as well as tools for monitoring genetic variation and assessing genetic consequences of captive breeding to adequately manage populations. An overview is given on quantitative genetics of farmed insects, how to record phenotypes and pedigrees, estimate genetic parameters, and design optimal breeding programmes. Lastly, the role of functional genetics in insect production is discussed, the biological link between DNA and phenotypic variation, and key to effectively apply genetic improvement strategies through selective breeding. This article identifies knowledge gaps in insect breeding and provides recommendations for application and future research. Major challenges in the field of genetics of farmed insects include how to phenotype large numbers of individual insects over generations; how environmental factors affect trait expression, including interaction with genetics; and how to translate results from laboratory settings to mass rearing environments. This article will contribute to further develop the area of genetics of insects for food and feed. | J13: demographic inference, insect breeding, population management, review, selection scheme
A14: 12 | B14: Smets et al. | C14: Common pitfalls and practical recommendations for chemical analysis of insect biomass | D14: 45632 | E14: 45787 | F14: 45807 | G14: https://doi.org/10.1163/23524588-bja10238 | H14: R. Smets, N.A. Sibinga, G. Verheyen, G. Rossi, M. Van Der Borght | I14: The rapid growth of the insect industry as a sustainable solution for feed, food, and biomaterials highlights the urgent need for standardised chemical analyses of insect biomass. Currently, the lack of standardised protocols has led to researchers employing diverse methodologies they perceive as most appropriate. This variability introduces the risk of inconsistency when comparing results, like comparing apples with oranges, and hampers progress in the field. Standardised methods of analysis for insect matrices are essential to ensure uniformity, reliability, and comparability of data, fostering trust and efficiency within the scientific and industrial communities. Establishing standard methods is the responsibility of specialized institutions like the Association of Official Agricultural Chemists or the International Organization for Standardization. Thus, rather than prescribing standard methods, the focus of this chapter is on identifying challenges with the current state-of-the-art, emphasizing the need for consensus-based approaches, and helping researchers interpret differences between the various methods reported in the literature. In the absence of standardised methods much can already be gained through provisional uniformization efforts. This chapter therefore outlines specific recommendations for sampling and key proximate analyses, including fat and fatty acid profiling, protein and amino acid quantification, ash determination, and the assessment of chitin, and nitrogen-free extract. Emphasis is also placed on the importance of accurate reporting, as documentation of methods will enhance data transparency, facilitate reproducibility, and strengthen cross-study comparisons. These efforts aim to streamline future research but also reduce inconsistencies in published data, ensuring the scientific community is no longer bugged by methodological uncertainties. | J14: chemical analysis, chitin, insects, moisture, protein
A15: 13 | B15: Smetana et al. | C15: Data analysis methods in studies of insects for food and feed | D15: 45626 | E15: 45741 | F15: 45798 | G15: https://doi.org/10.1163/23524588-bja10209 | H15: S. Smetana, C. Coudron, D. Deruytter, A. Francis, J.J. Pascual, T. Klammsteiner, N. Lemke, C. Sandrock, R. Zanoli | I15: In recent decades, research on insect production for food and feed has expanded significantly, driven by advances in farming, processing, genetics, and sustainability. Various data analysis methods, from traditional statistics to advanced machine learning, are used to optimise aspects of insect-based systems. In production, methods like analysis of variance (ANOVA) and regression analysis help improve breeding conditions and growth rates, while multivariate analyses support processing studies by evaluating nutritional and microbial safety. Genetic research leverages bioinformatics, genome-wide association studies (GWAS), and quantitative genetics to enhance traits like yield and disease resistance. Sustainability assessments use life cycle analysis (LCA) with Monte Carlo simulations to measure environmental impacts. Emerging tools, such as neural networks and support vector machines, are gaining traction for predicting feed conversion ratios and disease detection. Despite progress, a comprehensive guide that bridges classic and novel data analysis methods in insect research is still lacking. This study aims to address this gap by offering an accessible manual for researchers and professionals. It will consolidate methodologies across disciplines, highlighting foundational tools for beginners while showcasing advanced techniques for experts. Topics include the application of tailored methods like chitin and protein accounting, sensory analysis, consumer preference modelling, and data visualisation to improve stakeholder communication. By enhancing methodological rigor and fostering transparency, this guide will promote innovation, facilitate data interchange, and ensure the replicability of findings. Ultimately, it aims to drive sustainable advancements in the mass production of insects for food and feed. | J15: data analysis methods, genetic research, insect production, machine learning, sustainability assessment

Sheet contributions
A1: Chapter | B1: Author | C1: Affiliation_1 | D1: Affiliation_2 | E1: Institution | F1: City | G1: Country | H1: Lat | I1: Long | J1: ORCID
A2: 0 | B2: D. Deruytter | C2: Inagro vzw, 8800 Rumbeke-Beitem, Belgium | E2: Inagro | F2: Rumbeke-Beitem | G2: Belgium | H2: 50.901689 | I2: 3.124413 | J2: https://orcid.org/0000-0001-8565-2240
A3: 0 | B3: T. Veldkamp | C3: Wageningen Livestock Research, 6700 AH Wageningen, The Netherlands | E3: Wageningen University | F3: Wageningen | G3: The Netherlands | H3: 51.983874 | I3: 5.6589434 | J3: https://orcid.org/0000-0001-6880-9680
A4: 1 | B4: C.L. Coudron | C4: Inagro vzw, 8800 Rumbeke-Beitem, Belgium | E4: Inagro | F4: Rumbeke-Beitem | G4: Belgium | H4: 50.901689 | I4: 3.124413 | J4: https://orcid.org/0000-0002-0620-6187
A5: 1 | B5: C. Adamaki-Sotiraki | C5: Department of Agriculture, Crop Production and Rural Environment, University of Thessaly, 38446 Volos, Greece | E5: University of Thessaly | F5: Volos | G5: Greece | H5: 39.387934 | I5: 22.940509 | J5: https://orcid.org/0000-0002-0777-3634
A6: 1 | B6: W. Yakti | C6: Urban Plant Ecophysiology Division, Albrecht Daniel-Thaer Institute of Agriculture and Horticulture, Humboldt-Universität zu Berlin, 14195 Berlin, Germany | E6: Humboldt-Universität zu Berlin | F6: Berlin | G6: Germany | H6: 52.458027 | I6: 13.301789 | J6: https://orcid.org/0000-0003-2579-5586
A7: 1 | B7: J.J. Pascual | C7: Institute of Animal Science and Technology, Universitat Politècnica de València, 46022 Valencia, Spain | E7: Universitat Politècnica de València | F7: Valencia | G7: Spain | H7: 39.481963 | I7: -0.33822661 | J7: https://orcid.org/0000-0003-0737-5510
A8: 1 | B8: V. Wiklicky | C8: Department of Energy and Technology, Swedish University of Agricultural Sciences, 75007 Uppsala, Sweden | E8: University of Agricultural Sciences | F8: Uppsala | G8: Sweden | H8: 59.817039 | I8: 17.661906 | J8: https://orcid.org/0009-0007-3982-9544
A9: 1 | B9: C. Sandrock | C9: Department of Livestock Sciences, Research Institute of Organic Agriculture (FiBL), 5070 Frick, Switzerland | E9: FiBL | F9: Frick | G9: Switzerland | H9: 47.516528 | I9: 8.0255581 | J9: https://orcid.org/0000-0002-2054-2216
A10: 1 | B10: M. Van Peer | C10: Center of Expertise Sustainable Biomass and Chemistry, Thomas More University of Applied Sciences, 2440 Geel, Belgium | E10: Thomas More University of Applied Sciences | F10: Geel | G10: Belgium | H10: 51.160939 | I10: 4.961398 | J10: https://orcid.org/0000-0002-0256-928X
A11: 1 | B11: C.G. Athanassiou | C11: Department of Agriculture, Crop Production and Rural Environment, University of Thessaly, 38446 Volos, Greece | E11: University of Thessaly | F11: Volos | G11: Greece | H11: 39.387934 | I11: 22.940509 | J11: https://orcid.org/0000-0001-6578-4019
A12: 1 | B12: D.A. Peguero | C12: Department Sanitation, Water and Solid Waste for Development (Sandec), Eawag: Swiss Federal Institute of Aquatic Science and Technology, 8600 Dübendorf, Switzerland | E12: Eawag: Swiss Federal Institute of Aquatic Science and Technology | F12: Dübendorf | G12: Switzerland | H12: 47.403799 | I12: 8.6098383 | J12: https://orcid.org/0000-0001-9851-0882
A13: 1 | B13: C.I. Rumbos | C13: Department of Agriculture, School of Agricultural Sciences, University of Patras, 30200 Messolonghi, Greece | E13: University of Patras | F13: Messolonghi | G13: Greece | H13: 38.612411 | I13: 21.415228 | J13: https://orcid.org/0000-0002-3169-352X
... A44: 5 | B44: C. Svendsen | C44: UK Centre for Ecology and Hydrology, OX10 8BB Wallingford, United Kingdom | E44: UK Centre for Ecology and Hydrology | F44: Wallingford | G44: United Kingdom | H44: 51.602318 | I44: -1.1106435 | J44: https://orcid.org/0000-0001-7281-647X
A45: 5 | B45: M. Lloyd | C45: Department of Virology, Wageningen University and Research, 6708 PB Wageningen, The Netherlands | D45: Department of Genetics, University Institute of Biotechnology and Biomedicine (BIOTECMED), Universitat de València, 46100 Valencia, Spain | E45: Wageningen University | F45: Wageningen | G45: The Netherlands | H45: 51.986321 | I45: 5.6680296 | J45: https://orcid.org/0009-0000-8153-8029
A46: 5 | B46: L. Mugo-Kamiri | C46: Research Institute for the Biology of Insect, UMR CNRS 7261 University of Tours, avenue Monge, Parc Grandmont, 37200 Tours, France | D46: Centre for Ecology and Conservation, College of Life and Environmental Science, University of Exeter, TR10 9FE Penryn, UK | E46: University of Tours | F46: Tours | G46: France | H46: 47.355384 | I46: 0.70342543 | J46: https://orcid.org/0009-0008-6553-8457
A47: 5 | B47: J.M. Petersen | C47: Department of Virology, Wageningen University and Research, 6708 PB Wageningen, The Netherlands | D47: Institut de Recherche sur la Biologie de l’Insecte, CNRS – University of Tours, 37200 Tours, France | E47: Wageningen University | F47: Wageningen | G47: The Netherlands | H47: 51.986321 | I47: 5.6680296 | J47: https://orcid.org/0000-0002-2190-1401
A48: 5 | B48: E. Bessette | C48: Living Systems Institute, College of Life and Environmental Sciences, University of Exeter, EX4 4QD Exeter, United Kingdom | D48: Department of Plant and Environmental Sciences, University of Copenhagen, 1871 Frederiksberg C, Denmark | E48: University of Exeter | F48: Exeter | G48: United Kingdom | H48: 50.736886 | I48: -3.534669 | J48: https://orcid.org/0000-0001-7005-7182
A49: 5 | B49: S. Edwards | C49: Living Systems Institute, College of Life and Environmental Sciences, University of Exeter, EX4 4QD Exeter, United Kingdom | D49: Department of Plant and Environmental Sciences, University of Copenhagen, 1871 Frederiksberg C, Denmark | E49: University of Exeter | F49: Exeter | G49: United Kingdom | H49: 50.736886 | I49: -3.534669 | J49: https://orcid.org/0000-0002-2796-8527
A50: 5 | B50: F.S. Lim | C50: Department of Genetics, University Institute of Biotechnology and Biomedicine (BIOTECMED), Universitat de València, 46100 Valencia, Spain | D50: Institute of Biological Control, Julius Kühn-Institut (JKI), 69221 Dossenheim, Germany | E50: Universitat de València | F50: Valencia | G50: Spain | H50: 39.507659 | I50: -0.42133089 | J50: https://orcid.org/0000-0002-2650-7518
A51: 5 | B51: P. Herren | C51: UK Centre for Ecology and Hydrology, OX10 8BB Wallingford, United Kingdom | D51: Department of Plant and Environmental Sciences, University of Copenhagen, 1871 Frederiksberg C, Denmark | E51: UK Centre for Ecology and Hydrology | F51: Wallingford | G51: United Kingdom | H51: 51.602318 | I51: -1.1106435 | J51: https://orcid.org/0000-0002-8358-9636
A52: 5 | B52: L. Hernández Pelegrı́n | C52: Department of Virology, Wageningen University and Research, 6708 PB Wageningen, The Netherlands | D52: Department of Genetics, University Institute of Biotechnology and Biomedicine (BIOTECMED), Universitat de València, 46100 Valencia, Spain | E52: Wageningen University | F52: Wageningen | G52: The Netherlands | H52: 51.986321 | I52: 5.6680296 | J52: https://orcid.org/0000-0003-4910-4583
A53: 5 | B53: R.D. Pienaar | C53: Department of Genetics, University Institute of Biotechnology and Biomedicine (BIOTECMED), Universitat de València, 46100 Valencia, Spain | D53: Institut de Recherche sur la Biologie de l’Insecte, CNRS – University of Tours, 37200 Tours, France | E53: Universitat de València | F53: Valencia | G53: Spain | H53: 39.507659 | I53: -0.42133089 | J53: https://orcid.org/0000-0002-8797-9420
A54: 5 | B54: H. Huditz | C54: Department of Virology, Wageningen University and Research, 6708 PB Wageningen, The Netherlands | D54: Centre for Ecology and Conservation, College of Life and Environmental Science, University of Exeter, TR10 9FE Penryn, UK | E54: Wageningen University | F54: Wageningen | G54: The Netherlands | H54: 51.986321 | I54: 5.6680296 | J54: https://orcid.org/0000-0002-4278-1197
A55: 5 | B55: A. Mostafaie | C55: Department of Biology, Centre for Environmental and Marine Studies, University of Aveiro, 3810-193 Aveiro, Portugal | E55: University of Aveiro | F55: Aveiro | G55: Portugal | H55: 40.633778 | I55: -8.6593168 | J55: https://orcid.org/0000-0003-4268-4052
A56: 5 | B56: J. Pinto | C56: Department of Biology, Centre for Environmental and Marine Studies, University of Aveiro, 3810-193 Aveiro, Portugal | E56: University of Aveiro | F56: Aveiro | G56: Portugal | H56: 40.633778 | I56: -8.6593168 | J56: https://orcid.org/0000-0002-4901-5399
A57: 5 | B57: A. Roman | C57: Centre for Ecology and Conservation, College of Life and Environmental Science, University of Exeter, TR10 9FE Penryn, UK | D57: Department of Entomology, Wageningen University and Research, 6708 PB Wageningen, The Netherlands | E57: University of Exeter | F57: Penryn | G57: United Kingdom | H57: 50.170949 | I57: -5.1279704 | J57: https://orcid.org/0000-0002-8581-4737
A58: 5 | B58: C. Savio | C58: Department of Entomology, Wageningen University and Research, 6708 PB Wageningen, The Netherlands | D58: Micalis Institute, AgroParisTech, INRAE, Université Paris-Saclay, 78350 Jouy-en-Josas, France | E58: Wageningen University | F58: Wageningen | G58: The Netherlands | H58: 51.986334 | I58: 5.6680082 | J58: https://orcid.org/0000-0001-6600-8126
A59: 5 | B59: A.R. Slowik | C59: UK Centre for Ecology and Hydrology, OX10 8BB Wallingford, United Kingdom | D59: Department of Plant and Environmental Sciences, University of Copenhagen, 1871 Frederiksberg C, Denmark | E59: UK Centre for Ecology and Hydrology | F59: Wallingford | G59: United Kingdom | H59: 51.602318 | I59: -1.1106435 | J59: https://orcid.org/0000-0003-3079-3868
A60: 5 | B60: J. Takacs | C60: Department of Virology, Wageningen University and Research, 6708 PB Wageningen, The Netherlands | D60: Department of Plant and Environmental Sciences, University of Copenhagen, 1871 Frederiksberg C, Denmark | E60: Wageningen University | F60: Wageningen | G60: The Netherlands | H60: 51.986321 | I60: 5.6680296 | J60: https://orcid.org/0000-0002-7564-7023
A61: 5 | B61: J.K. Upfold | C61: Department of Plant and Environmental Sciences, University of Copenhagen, 1871 Frederiksberg C, Denmark | D61: Micalis Institute, AgroParisTech, INRAE, Université Paris-Saclay, 78350 Jouy-en-Josas, France | E61: University of Copenhagen | F61: Copenhagen | G61: Denmark | H61: 55.683617 | I61: 12.544698 | J61: https://orcid.org/0000-0002-8325-4262
A62: 5 | B62: H. Hesketh | C62: UK Centre for Ecology and Hydrology, OX10 8BB Wallingford, United Kingdom | E62: UK Centre for Ecology and Hydrology | F62: Wallingford | G62: United Kingdom | H62: 51.602318 | I62: -1.1106435 | J62: https://orcid.org/0000-0003-1794-7658
A63: 6 | B63: I.G. Lopes | C63: Department of Biosystems and Technology, Swedish University of Agricultural Sciences, 234 56 Alnarp, Sweden | E63: University of Agricultural Sciences | F63: Alnarp | G63: Sweden | H63: 55.659884 | I63: 13.075877 | J63: https://orcid.org/0000-0003-0381-7537
A64: 6 | B64: M. Gómez-Brandón | C64: Grupo de Ecología Animal (GEA), Torre CACTI-Lab 95, Vigo University, 36310 Vigo, Spain | E64: Vigo University | F64: Vigo | G64: Spain | H64: 42.1672 | I64: -8.6840566 | J64: https://orcid.org/0000-0003-4744-535X
A65: 6 | B65: N. Praeg | C65: Department of Microbiology, Universität Innsbruck, Technikerstrasse 25, 6020 Innsbruck, Austria | E65: Universität Innsbruck | F65: Innsbruck | G65: Austria | H65: 47.264926 | I65: 11.342091 | J65: https://orcid.org/0000-0002-1531-8543
A66: 6 | B66: J. Claeys | C66: Inagro vzw, 8800 Rumbeke-Beitem, Belgium | E66: Inagro | F66: Rumbeke-Beitem | G66: Belgium | H66: 50.901689 | I66: 3.124413 | J66: https://orcid.org/0000-0003-2167-7865
A67: 6 | B67: W. Yakti | C67: Urban Plant Ecophysiology Division, Albrecht Daniel-Thaer Institute of Agriculture and Horticulture, Humboldt-Universität zu Berlin, 14195 Berlin, Germany | E67: Humboldt-Universität zu Berlin | F67: Berlin | G67: Germany | H67: 52.458027 | I67: 13.301789 | J67: https://orcid.org/0000-0003-2579-5586
A68: 6 | B68: M. Bitterlich | C68: Urban Plant Ecophysiology Division, Albrecht Daniel-Thaer Institute of Agriculture and Horticulture, Humboldt-Universität zu Berlin, 14195 Berlin, Germany | E68: Humboldt-Universität zu Berlin | F68: Berlin | G68: Germany | H68: 52.458027 | I68: 13.301789 | J68: https://orcid.org/0000-0002-3562-7327
A69: 6 | B69: J.J. Jones | C69: Department of Biosystems Engineering, Albrecht Daniel Thaer-Institute of Agricultural and Horticultural Sciences, Humboldt-University zu Berlin, 14195 Berlin, Germany | E69: Humboldt-Universität zu Berlin | F69: Berlin | G69: Germany | H69: 52.458027 | I69: 13.301789 | J69: https://orcid.org/0000-0001-5652-408X
A70: 6 | B70: C.-M. Geilfus | C70: Department of Soil Science and Plant Nutrition, Hochschule Geisenheim, 65366 Geisenheim, Germany | E70: Hochschule Geisenheim | F70: Geisenheim | G70: Germany | H70: 49.98437 | I70: 7.961393 | J70: https://orcid.org/0000-0002-9820-8111
...

Sheet unique_authors
A1: # | B1: Authors | C1: Institution | D1: ORCID
A2: 1 | B2: {=_xlfn._xlws.SORT(_xlfn.UNIQUE(contributions!B2:B150))} -> A. Francis | C2: =VLOOKUP(B2,contributions!B:H,4,FALSE) -> DIL e.V. | D2: =VLOOKUP(B2,contributions!B:J,9,FALSE) -> https://orcid.org/0000-0003-2813-9277
A3: 2 | B3: A. Montali | C3: =VLOOKUP(B3,contributions!B:H,4,FALSE) -> University of Insubria | D3: =VLOOKUP(B3,contributions!B:J,9,FALSE) -> https://orcid.org/0000-0001-8144-9624
A4: 3 | B4: A. Mostafaie | C4: =VLOOKUP(B4,contributions!B:H,4,FALSE) -> University of Aveiro | D4: =VLOOKUP(B4,contributions!B:J,9,FALSE) -> https://orcid.org/0000-0003-4268-4052
A5: 4 | B5: A. Roman | C5: =VLOOKUP(B5,contributions!B:H,4,FALSE) -> University of Exeter | D5: =VLOOKUP(B5,contributions!B:J,9,FALSE) -> https://orcid.org/0000-0002-8581-4737
A6: 5 | B6: A.C. Bouwman | C6: =VLOOKUP(B6,contributions!B:H,4,FALSE) -> Wageningen University | D6: =VLOOKUP(B6,contributions!B:J,9,FALSE) -> https://orcid.org/0000-0001-5079-7108
A7: 6 | B7: A.P. Parodi | C7: =VLOOKUP(B7,contributions!B:H,4,FALSE) -> Wageningen University | D7: =VLOOKUP(B7,contributions!B:J,9,FALSE) -> https://orcid.org/0000-0003-1351-138X
A8: 7 | B8: A.R. Slowik | C8: =VLOOKUP(B8,contributions!B:H,4,FALSE) -> UK Centre for Ecology and Hydrology | D8: =VLOOKUP(B8,contributions!B:J,9,FALSE) -> https://orcid.org/0000-0003-3079-3868
A9: 8 | B9: A.R.R. Silva | C9: =VLOOKUP(B9,contributions!B:H,4,FALSE) -> University of Aveiro | D9: =VLOOKUP(B9,contributions!B:J,9,FALSE) -> https://orcid.org/0000-0003-0689-639X
A10: 9 | B10: B.A. Pannebakker | C10: =VLOOKUP(B10,contributions!B:H,4,FALSE) -> Wageningen University | D10: =VLOOKUP(B10,contributions!B:J,9,FALSE) -> https://orcid.org/0000-0001-8503-3896
A11: 10 | B11: C. Adamaki-Sotiraki | C11: =VLOOKUP(B11,contributions!B:H,4,FALSE) -> University of Thessaly | D11: =VLOOKUP(B11,contributions!B:J,9,FALSE) -> https://orcid.org/0000-0002-0777-3634
A12: 11 | B12: C. Bressac | C12: =VLOOKUP(B12,contributions!B:H,4,FALSE) -> University of Tours | D12: =VLOOKUP(B12,contributions!B:J,9,FALSE) -> https://orcid.org/0000-0001-7609-8970
A13: 12 | B13: C. Rhode | C13: =VLOOKUP(B13,contributions!B:H,4,FALSE) -> Stellenbosch University | D13: =VLOOKUP(B13,contributions!B:J,9,FALSE) -> https://orcid.org/0000-0001-7969-7282
A14: 13 | B14: C. Rumbos | C14: =VLOOKUP(B14,contributions!B:H,4,FALSE) -> University of Patras | D14: =VLOOKUP(B14,contributions!B:J,9,FALSE) -> https://orcid.org/0000-0002-3169-352X
... A110: 109 | B110: W. Yakti | C110: =VLOOKUP(B110,contributions!B:H,4,FALSE) -> Humboldt-Universität zu Berlin | D110: =VLOOKUP(B110,contributions!B:J,9,FALSE) -> https://orcid.org/0000-0003-2579-5586
